<?xml version="1.0" ?>
<!-- =================================================================================== -->
<!-- |    This document was autogenerated by xacro from urdf\spiderV3C_clear.xacro.temp | -->
<!-- |    EDITING THIS FILE BY HAND IS NOT RECOMMENDED                                 | -->
<!-- =================================================================================== -->
<robot xmlns:xacro="http://www.ros.org/wiki/xacro" name="spiderV3C_clear">
  <material name="silver">
    <color rgba="0.700 0.700 0.700 1.000"/>
  </material>
  <transmission name="Revolute 1_tran">
    <type>transmission_interface/SimpleTransmission</type>
    <joint name="Revolute 1">
      <hardwareInterface>hardware_interface/EffortJointInterface</hardwareInterface>
    </joint>
    <actuator name="Revolute 1_actr">
      <hardwareInterface>hardware_interface/EffortJointInterface</hardwareInterface>
      <mechanicalReduction>1</mechanicalReduction>
    </actuator>
  </transmission>
  <transmission name="Revolute 2_tran">
    <type>transmission_interface/SimpleTransmission</type>
    <joint name="Revolute 2">
      <hardwareInterface>hardware_interface/EffortJointInterface</hardwareInterface>
    </joint>
    <actuator name="Revolute 2_actr">
      <hardwareInterface>hardware_interface/EffortJointInterface</hardwareInterface>
      <mechanicalReduction>1</mechanicalReduction>
    </actuator>
  </transmission>
  <transmission name="Revolute 3_tran">
    <type>transmission_interface/SimpleTransmission</type>
    <joint name="Revolute 3">
      <hardwareInterface>hardware_interface/EffortJointInterface</hardwareInterface>
    </joint>
    <actuator name="Revolute 3_actr">
      <hardwareInterface>hardware_interface/EffortJointInterface</hardwareInterface>
      <mechanicalReduction>1</mechanicalReduction>
    </actuator>
  </transmission>
  <transmission name="Revolute 4_tran">
    <type>transmission_interface/SimpleTransmission</type>
    <joint name="Revolute 4">
      <hardwareInterface>hardware_interface/EffortJointInterface</hardwareInterface>
    </joint>
    <actuator name="Revolute 4_actr">
      <hardwareInterface>hardware_interface/EffortJointInterface</hardwareInterface>
      <mechanicalReduction>1</mechanicalReduction>
    </actuator>
  </transmission>
  <transmission name="Revolute 5_tran">
    <type>transmission_interface/SimpleTransmission</type>
    <joint name="Revolute 5">
      <hardwareInterface>hardware_interface/EffortJointInterface</hardwareInterface>
    </joint>
    <actuator name="Revolute 5_actr">
      <hardwareInterface>hardware_interface/EffortJointInterface</hardwareInterface>
      <mechanicalReduction>1</mechanicalReduction>
    </actuator>
  </transmission>
  <transmission name="Revolute 6_tran">
    <type>transmission_interface/SimpleTransmission</type>
    <joint name="Revolute 6">
      <hardwareInterface>hardware_interface/EffortJointInterface</hardwareInterface>
    </joint>
    <actuator name="Revolute 6_actr">
      <hardwareInterface>hardware_interface/EffortJointInterface</hardwareInterface>
      <mechanicalReduction>1</mechanicalReduction>
    </actuator>
  </transmission>
  <transmission name="Revolute 7_tran">
    <type>transmission_interface/SimpleTransmission</type>
    <joint name="Revolute 7">
      <hardwareInterface>hardware_interface/EffortJointInterface</hardwareInterface>
    </joint>
    <actuator name="Revolute 7_actr">
      <hardwareInterface>hardware_interface/EffortJointInterface</hardwareInterface>
      <mechanicalReduction>1</mechanicalReduction>
    </actuator>
  </transmission>
  <transmission name="Revolute 8_tran">
    <type>transmission_interface/SimpleTransmission</type>
    <joint name="Revolute 8">
      <hardwareInterface>hardware_interface/EffortJointInterface</hardwareInterface>
    </joint>
    <actuator name="Revolute 8_actr">
      <hardwareInterface>hardware_interface/EffortJointInterface</hardwareInterface>
      <mechanicalReduction>1</mechanicalReduction>
    </actuator>
  </transmission>
  <!-- omitted .gazebo include -->
  <link name="base_link">
    <inertial>
      <origin xyz="1.0872043557683421e-12 0.03772456007506391 -9.76875493552546e-11" rpy="0 0 0"/>
      <mass value="0.38585922265788586"/>
      <inertia ixx="0.000601" iyy="0.000686" izz="0.000132" ixy="0.0" iyz="-0.0" ixz="-2e-06"/>
    </inertial>
    <visual>
      <origin xyz="0 0 0" rpy="0 0 0"/>
      <geometry>
        <mesh filename="package://spiderV3C_clear_description/meshes/base_link.stl" scale="0.001 0.001 0.001"/>
      </geometry>
      <material name="silver"/>
    </visual>
    <collision>
      <origin xyz="0 0 0" rpy="0 0 0"/>
      <geometry>
        <mesh filename="package://spiderV3C_clear_description/meshes/base_link.stl" scale="0.001 0.001 0.001"/>
      </geometry>
    </collision>
  </link>
  <link name="shelfCom_clear_onePart3B_v1_1">
    <inertial>
      <origin xyz="1.282220926688421e-06 -4.917382889768618e-10 0.020000464804861617" rpy="0 0 0"/>
      <mass value="0.10441449723026225"/>
      <inertia ixx="2.7e-05" iyy="2.7e-05" izz="2.5e-05" ixy="-0.0" iyz="0.0" ixz="0.0"/>
    </inertial>
    <visual>
      <origin xyz="-0.021659 -0.038 -0.040055" rpy="0 0 0"/>
      <geometry>
        <mesh filename="package://spiderV3C_clear_description/meshes/shelfCom_clear_onePart3B_v1_1.stl" scale="0.001 0.001 0.001"/>
      </geometry>
      <material name="silver"/>
    </visual>
    <collision>
      <origin xyz="-0.021659 -0.038 -0.040055" rpy="0 0 0"/>
      <geometry>
        <mesh filename="package://spiderV3C_clear_description/meshes/shelfCom_clear_onePart3B_v1_1.stl" scale="0.001 0.001 0.001"/>
      </geometry>
    </collision>
  </link>
  <link name="shelfCom_clear_onePart3B_v1__1__1">
    <inertial>
      <origin xyz="1.2822209267022988e-06 -4.917383306102252e-10 0.020000464983675574" rpy="0 0 0"/>
      <mass value="0.10441449723026225"/>
      <inertia ixx="2.7e-05" iyy="2.7e-05" izz="2.5e-05" ixy="-0.0" iyz="0.0" ixz="0.0"/>
    </inertial>
    <visual>
      <origin xyz="0.021341 -0.038 -0.040055" rpy="0 0 0"/>
      <geometry>
        <mesh filename="package://spiderV3C_clear_description/meshes/shelfCom_clear_onePart3B_v1__1__1.stl" scale="0.001 0.001 0.001"/>
      </geometry>
      <material name="silver"/>
    </visual>
    <collision>
      <origin xyz="0.021341 -0.038 -0.040055" rpy="0 0 0"/>
      <geometry>
        <mesh filename="package://spiderV3C_clear_description/meshes/shelfCom_clear_onePart3B_v1__1__1.stl" scale="0.001 0.001 0.001"/>
      </geometry>
    </collision>
  </link>
  <link name="shelfCom_clear_onePart3B_v1__2__1">
    <inertial>
      <origin xyz="-1.2822209267300544e-06 -4.917382820379679e-10 -0.020000464804861562" rpy="0 0 0"/>
      <mass value="0.10441449723026225"/>
      <inertia ixx="2.7e-05" iyy="2.7e-05" izz="2.5e-05" ixy="0.0" iyz="-0.0" ixz="-0.0"/>
    </inertial>
    <visual>
      <origin xyz="0.021659 -0.038 0.040055" rpy="0 0 0"/>
      <geometry>
        <mesh filename="package://spiderV3C_clear_description/meshes/shelfCom_clear_onePart3B_v1__2__1.stl" scale="0.001 0.001 0.001"/>
      </geometry>
      <material name="silver"/>
    </visual>
    <collision>
      <origin xyz="0.021659 -0.038 0.040055" rpy="0 0 0"/>
      <geometry>
        <mesh filename="package://spiderV3C_clear_description/meshes/shelfCom_clear_onePart3B_v1__2__1.stl" scale="0.001 0.001 0.001"/>
      </geometry>
    </collision>
  </link>
  <link name="shelfCom_clear_onePart3B_v1__3__1">
    <inertial>
      <origin xyz="6.451693708095507e-07 -4.917383028546496e-10 -0.020000464983675525" rpy="0 0 0"/>
      <mass value="0.10441449723026225"/>
      <inertia ixx="2.7e-05" iyy="2.7e-05" izz="2.5e-05" ixy="0.0" iyz="0.0" ixz="-0.0"/>
    </inertial>
    <visual>
      <origin xyz="-0.021341 -0.038 0.040055" rpy="0 0 0"/>
      <geometry>
        <mesh filename="package://spiderV3C_clear_description/meshes/shelfCom_clear_onePart3B_v1__3__1.stl" scale="0.001 0.001 0.001"/>
      </geometry>
      <material name="silver"/>
    </visual>
    <collision>
      <origin xyz="-0.021341 -0.038 0.040055" rpy="0 0 0"/>
      <geometry>
        <mesh filename="package://spiderV3C_clear_description/meshes/shelfCom_clear_onePart3B_v1__3__1.stl" scale="0.001 0.001 0.001"/>
      </geometry>
    </collision>
  </link>
  <link name="Motorfoot_clearB_v1_1">
    <inertial>
      <origin xyz="-0.0005548861990964382 -0.004104756311087046 0.005767863519832106" rpy="0 0 0"/>
      <mass value="0.08632102355113754"/>
      <inertia ixx="1.2e-05" iyy="1.3e-05" izz="1e-05" ixy="-0.0" iyz="4e-06" ixz="0.0"/>
    </inertial>
    <visual>
      <origin xyz="-0.02166 -0.037999 -0.080055" rpy="0 0 0"/>
      <geometry>
        <mesh filename="package://spiderV3C_clear_description/meshes/Motorfoot_clearB_v1_1.stl" scale="0.001 0.001 0.001"/>
      </geometry>
      <material name="silver"/>
    </visual>
    <collision>
      <origin xyz="-0.02166 -0.037999 -0.080055" rpy="0 0 0"/>
      <geometry>
        <mesh filename="package://spiderV3C_clear_description/meshes/Motorfoot_clearB_v1_1.stl" scale="0.001 0.001 0.001"/>
      </geometry>
    </collision>
  </link>
  <link name="Motorfoot_clearB_v1__1__1">
    <inertial>
      <origin xyz="-0.0005548861990964278 -0.004104756311087088 0.005767863698645959" rpy="0 0 0"/>
      <mass value="0.08632102355113754"/>
      <inertia ixx="1.2e-05" iyy="1.3e-05" izz="1e-05" ixy="-0.0" iyz="4e-06" ixz="0.0"/>
    </inertial>
    <visual>
      <origin xyz="0.02134 -0.037999 -0.080055" rpy="0 0 0"/>
      <geometry>
        <mesh filename="package://spiderV3C_clear_description/meshes/Motorfoot_clearB_v1__1__1.stl" scale="0.001 0.001 0.001"/>
      </geometry>
      <material name="silver"/>
    </visual>
    <collision>
      <origin xyz="0.02134 -0.037999 -0.080055" rpy="0 0 0"/>
      <geometry>
        <mesh filename="package://spiderV3C_clear_description/meshes/Motorfoot_clearB_v1__1__1.stl" scale="0.001 0.001 0.001"/>
      </geometry>
    </collision>
  </link>
  <link name="Motorfoot_clearB_v1__2__1">
    <inertial>
      <origin xyz="0.0005548135893939481 -0.004104756311087074 -0.005767863698645986" rpy="0 0 0"/>
      <mass value="0.08632102355113754"/>
      <inertia ixx="1.2e-05" iyy="1.3e-05" izz="1e-05" ixy="0.0" iyz="-4e-06" ixz="0.0"/>
    </inertial>
    <visual>
      <origin xyz="-0.021342 -0.037999 0.080055" rpy="0 0 0"/>
      <geometry>
        <mesh filename="package://spiderV3C_clear_description/meshes/Motorfoot_clearB_v1__2__1.stl" scale="0.001 0.001 0.001"/>
      </geometry>
      <material name="silver"/>
    </visual>
    <collision>
      <origin xyz="-0.021342 -0.037999 0.080055" rpy="0 0 0"/>
      <geometry>
        <mesh filename="package://spiderV3C_clear_description/meshes/Motorfoot_clearB_v1__2__1.stl" scale="0.001 0.001 0.001"/>
      </geometry>
    </collision>
  </link>
  <link name="Motorfoot_clearB_v1__3__1">
    <inertial>
      <origin xyz="-0.0005554506409498755 -0.004015624329770193 -0.005830274405045688" rpy="0 0 0"/>
      <mass value="0.08632102355113754"/>
      <inertia ixx="1.2e-05" iyy="1.3e-05" izz="1e-05" ixy="-0.0" iyz="-4e-06" ixz="-0.0"/>
    </inertial>
    <visual>
      <origin xyz="0.02166 -0.037999 0.080055" rpy="0 0 0"/>
      <geometry>
        <mesh filename="package://spiderV3C_clear_description/meshes/Motorfoot_clearB_v1__3__1.stl" scale="0.001 0.001 0.001"/>
      </geometry>
      <material name="silver"/>
    </visual>
    <collision>
      <origin xyz="0.02166 -0.037999 0.080055" rpy="0 0 0"/>
      <geometry>
        <mesh filename="package://spiderV3C_clear_description/meshes/Motorfoot_clearB_v1__3__1.stl" scale="0.001 0.001 0.001"/>
      </geometry>
    </collision>
  </link>
  <joint name="Revolute 1" type="revolute">
    <origin xyz="0.021659 0.038 0.040055" rpy="0 0 0"/>
    <parent link="base_link"/>
    <child link="shelfCom_clear_onePart3B_v1_1"/>
    <axis xyz="0.0 1.0 -0.0"/>
    <limit upper="2.094395" lower="0.0" effort="100" velocity="100"/>
  </joint>
  <joint name="Revolute 2" type="revolute">
    <origin xyz="-0.021341 0.038 0.040055" rpy="0 0 0"/>
    <parent link="base_link"/>
    <child link="shelfCom_clear_onePart3B_v1__1__1"/>
    <axis xyz="0.0 -1.0 -0.0"/>
    <limit upper="2.094395" lower="0.0" effort="100" velocity="100"/>
  </joint>
  <joint name="Revolute 3" type="revolute">
    <origin xyz="-0.021659 0.038 -0.040055" rpy="0 0 0"/>
    <parent link="base_link"/>
    <child link="shelfCom_clear_onePart3B_v1__2__1"/>
    <axis xyz="-0.0 1.0 0.0"/>
    <limit upper="2.094395" lower="0.0" effort="100" velocity="100"/>
  </joint>
  <joint name="Revolute 4" type="revolute">
    <origin xyz="0.021341 0.038 -0.040055" rpy="0 0 0"/>
    <parent link="base_link"/>
    <child link="shelfCom_clear_onePart3B_v1__3__1"/>
    <axis xyz="-0.0 -1.0 -0.0"/>
    <limit upper="2.094395" lower="0.0" effort="100" velocity="100"/>
  </joint>
  <joint name="Revolute 5" type="revolute">
    <origin xyz="1e-06 -1e-06 0.04" rpy="0 0 0"/>
    <parent link="shelfCom_clear_onePart3B_v1_1"/>
    <child link="Motorfoot_clearB_v1_1"/>
    <axis xyz="1.0 -0.0 0.0"/>
    <limit upper="1.745329" lower="0.0" effort="100" velocity="100"/>
  </joint>
  <joint name="Revolute 6" type="revolute">
    <origin xyz="1e-06 -1e-06 0.04" rpy="0 0 0"/>
    <parent link="shelfCom_clear_onePart3B_v1__1__1"/>
    <child link="Motorfoot_clearB_v1__1__1"/>
    <axis xyz="1.0 -0.0 0.0"/>
    <limit upper="1.745329" lower="0.0" effort="100" velocity="100"/>
  </joint>
  <joint name="Revolute 7" type="revolute">
    <origin xyz="1e-06 -1e-06 -0.04" rpy="0 0 0"/>
    <parent link="shelfCom_clear_onePart3B_v1__3__1"/>
    <child link="Motorfoot_clearB_v1__2__1"/>
    <axis xyz="-1.0 -0.0 0.0"/>
    <limit upper="1.745329" lower="0.0" effort="100" velocity="100"/>
  </joint>
  <joint name="Revolute 8" type="revolute">
    <origin xyz="-1e-06 -1e-06 -0.04" rpy="0 0 0"/>
    <parent link="shelfCom_clear_onePart3B_v1__2__1"/>
    <child link="Motorfoot_clearB_v1__3__1"/>
    <axis xyz="-1.0 -0.0 0.0"/>
    <limit upper="1.745329" lower="0.0" effort="100" velocity="100"/>
  </joint>
</robot>
